[2015-10-13 18:50:16,357] INFO - started: 1444733416
[2015-10-13 18:50:16,358] INFO - yml_temp_name: python2.7
[2015-10-13 18:50:16,358] INFO - args: {'host': u'python-test', 'user': u'root'}
[2015-10-13 18:50:26,947] INFO - status: {'python-test': {'unreachable': 1, 'skipped': 0, 'ok': 0, 'changed': 0, 'failures': 0}}
[2015-10-13 18:50:38,669] INFO - started: 1444733438
[2015-10-13 18:50:38,670] INFO - yml_temp_name: python2.7
[2015-10-13 18:50:38,670] INFO - args: {'host': u'python-test', 'user': u'root'}
[2015-10-13 18:50:49,189] INFO - status: {'python-test': {'unreachable': 1, 'skipped': 0, 'ok': 0, 'changed': 0, 'failures': 0}}
[2015-10-13 18:52:53,421] INFO - started: 1444733573
[2015-10-13 18:52:53,421] INFO - yml_temp_name: python2.7
[2015-10-13 18:52:53,421] INFO - args: {'host': u'python-test', 'user': u'root'}
[2015-10-13 18:53:08,933] INFO - status: {'python-test': {'unreachable': 1, 'skipped': 0, 'ok': 0, 'changed': 0, 'failures': 0}}
[2015-10-13 18:54:08,165] INFO - started: 1444733648
[2015-10-13 18:54:08,165] INFO - yml_temp_name: python2.7
[2015-10-13 18:54:08,165] INFO - args: {'host': u'python-test', 'user': u'root'}
[2015-10-13 18:56:40,027] ERROR - Traceback (most recent call last):
  File "amqp_consumer_daemon.py", line 90, in run
    chan.wait()
  File "/usr/local/lib/python2.7/site-packages/amqplib/client_0_8/abstract_channel.py", line 97, in wait
    return self.dispatch_method(method_sig, args, content)
  File "/usr/local/lib/python2.7/site-packages/amqplib/client_0_8/abstract_channel.py", line 117, in dispatch_method
    return amqp_method(self, args, content)
  File "/usr/local/lib/python2.7/site-packages/amqplib/client_0_8/channel.py", line 2060, in _basic_deliver
    func(msg)
  File "amqp_consumer_daemon.py", line 70, in recv_callback
    db.execute(upd_jobs_sql, pickle.dumps(status), finished, started)
  File "/usr/local/lib/python2.7/site-packages/torndb.py", line 160, in execute
    return self.execute_lastrowid(query, *parameters, **kwparameters)
  File "/usr/local/lib/python2.7/site-packages/torndb.py", line 166, in execute_lastrowid
    self._execute(cursor, query, parameters, kwparameters)
  File "/usr/local/lib/python2.7/site-packages/torndb.py", line 234, in _execute
    return cursor.execute(query, kwparameters or parameters)
  File "/usr/local/lib/python2.7/site-packages/MySQLdb/cursors.py", line 205, in execute
    self.errorhandler(self, exc, value)
  File "/usr/local/lib/python2.7/site-packages/MySQLdb/connections.py", line 36, in defaulterrorhandler
    raise errorclass, errorvalue
OperationalError: (2006, 'MySQL server has gone away')

[2015-10-13 18:59:59,198] INFO - started: 1444733999
[2015-10-13 18:59:59,199] INFO - yml_temp_name: python2.7
[2015-10-13 18:59:59,199] INFO - args: {'host': u'python-test', 'user': u'root'}
[2015-10-13 19:01:25,392] INFO - status: {'python-test': {'unreachable': 0, 'skipped': 1, 'ok': 15, 'changed': 6, 'failures': 0}}
